Test obtanied using python's unit tet library
PS C:\Users\MartT\Downloads\Assignment 2 attached files Oct 4, 2024 201 PM> & C:/Python312/python.exe "c:/Users/MartT/Downloads/Assignment 2 attached files Oct 4, 2024 201 PM/a2_part_2_300403489.py"
(7, 8)
PS C:\Users\MartT\Downloads\Assignment 2 attached files Oct 4, 2024 201 PM> & C:/Python312/python.exe "c:/Users/MartT/Downloads/Assignment 2 attached files Oct 4, 2024 201 PM/a2_part_2_300403489.py"
(9, 4)
PS C:\Users\MartT\Downloads\Assignment 2 attached files Oct 4, 2024 201 PM> & C:/Python312/python.exe "c:/Users/MartT/Downloads/Assignment 2 attached files Oct 4, 2024 201 PM/a2_part_2_300403489.py"
(9, 4)
PS C:\Users\MartT\Downloads\Assignment 2 attached files Oct 4, 2024 201 PM> & C:/Python312/python.exe "c:/Users/MartT/Downloads/Assignment 2 attached files Oct 4, 2024 201 PM/a2_part_2_300403489.py"
(9, 4.127999999999986)
PS C:\Users\MartT\Downloads\Assignment 2 attached files Oct 4, 2024 201 PM> & C:/Python312/python.exe "c:/Users/MartT/Downloads/Assignment 2 attached files Oct 4, 2024 201 PM/a2_part_2_300403489.py"
(9, 4.0)
PS C:\Users\MartT\Downloads\Assignment 2 attached files Oct 4, 2024 201 PM> & C:/Python312/python.exe "c:/Users/MartT/Downloads/Assignment 2 attached files Oct 4, 2024 201 PM/a2_part_2_300403489.py"
(7, 8.0)
PS C:\Users\MartT\Downloads\Assignment 2 attached files Oct 4, 2024 201 PM> & C:/Python312/python.exe "c:/Users/MartT/Downloads/Assignment 2 attached files Oct 4, 2024 201 PM/unit_tests.py"
Please enter the radius of the circle: 3
Please enter the x coordinate of the center: 33
Please enter the y coordinate of the center: 33
(30.0, 30.0)
.F...
======================================================================
FAIL: test_negative_numbers (__main__.TestL2LOFunction.test_negative_numbers)
----------------------------------------------------------------------
Traceback (most recent call last):
  File "c:\Users\MartT\Downloads\Assignment 2 attached files Oct 4, 2024 201 PM\unit_tests.py", line 15, in test_negative_numbers
    with self.assertRaises(ValueError):
         ^^^^^^^^^^^^^^^^^^^^^^^^^^^^^
AssertionError: ValueError not raised

----------------------------------------------------------------------
Ran 5 tests in 0.001s

FAILED (failures=1)
PS C:\Users\MartT\Downloads\Assignment 2 attached files Oct 4, 2024 201 PM> & C:/Python312/python.exe "c:/Users/MartT/Downloads/Assignment 2 attached files Oct 4, 2024 201 PM/unit_tests.py"
Please enter the radius of the circle: j
Traceback (most recent call last):
  File "c:\Users\MartT\Downloads\Assignment 2 attached files Oct 4, 2024 201 PM\unit_tests.py", line 2, in <module>
    from a2_part_2_300403489 import *
  File "c:\Users\MartT\Downloads\Assignment 2 attached files Oct 4, 2024 201 PM\a2_part_2_300403489.py", line 84, in <module>
    radius = float(input("Please enter the radius of the circle: "))
             ^^^^^^^^^^^^^^^^^^^^^^^^^^^^^^^^^^^^^^^^^^^^^^^^^^^^^^^
ValueError: could not convert string to float: 'j'
PS C:\Users\MartT\Downloads\Assignment 2 attached files Oct 4, 2024 201 PM> & C:/Python312/python.exe "c:/Users/MartT/Downloads/Assignment 2 attached files Oct 4, 2024 201 PM/unit_tests.py"
Please enter the radius of the circle: 2
Please enter the x coordinate of the center: 3
Please enter the y coordinate of the center: 4
(1.0, 2.0)
....
----------------------------------------------------------------------
Ran 4 tests in 0.000s

OK
PS C:\Users\MartT\Downloads\Assignment 2 attached files Oct 4, 2024 201 PM> & C:/Python312/python.exe "c:/Users/MartT/Downloads/Assignment 2 attached files Oct 4, 2024 201 PM/unit_tests.py"
Please enter the radius of the circle: 3
Please enter the x coordinate of the center: 5
Please enter the y coordinate of the center: 2
(2.0, -1.0)
...F..
======================================================================
FAIL: test_majority_vote (__main__.TestVoteFunction.test_majority_vote)
----------------------------------------------------------------------
Traceback (most recent call last):
  File "C:\Python312\Lib\unittest\mock.py", line 1393, in patched
    return func(*newargs, **newkeywargs)
           ^^^^^^^^^^^^^^^^^^^^^^^^^^^^^
  File "c:\Users\MartT\Downloads\Assignment 2 attached files Oct 4, 2024 201 PM\unit_tests.py", line 25, in test_majority_vote
    mock_print.assert_called_with("proposal passes with majority")
  File "C:\Python312\Lib\unittest\mock.py", line 947, in assert_called_with
    raise AssertionError(_error_message()) from cause
AssertionError: expected call not found.
Expected: print('proposal passes with majority')
  Actual: print('proposal fails')

----------------------------------------------------------------------
Ran 6 tests in 0.005s

FAILED (failures=1)
PS C:\Users\MartT\Downloads\Assignment 2 attached files Oct 4, 2024 201 PM> & C:/Python312/python.exe "c:/Users/MartT/Downloads/Assignment 2 attached files Oct 4, 2024 201 PM/unit_tests.py"
Please enter the radius of the circle: 23
Please enter the x coordinate of the center: 42
Please enter the y coordinate of the center: 5325
(19.0, 5302.0)
.....
----------------------------------------------------------------------
Ran 5 tests in 0.001s

OK
PS C:\Users\MartT\Downloads\Assignment 2 attached files Oct 4, 2024 201 PM> 